[2024-03-21T03:04:00.541+0000] {taskinstance.py:1956} INFO - Dependencies all met for dep_context=non-requeueable deps ti=<TaskInstance: my_dag.choose_best_model manual__2024-03-21T03:03:56.204458+00:00 [queued]>
[2024-03-21T03:04:00.564+0000] {taskinstance.py:1956} INFO - Dependencies all met for dep_context=requeueable deps ti=<TaskInstance: my_dag.choose_best_model manual__2024-03-21T03:03:56.204458+00:00 [queued]>
[2024-03-21T03:04:00.565+0000] {taskinstance.py:2170} INFO - Starting attempt 1 of 1
[2024-03-21T03:04:00.613+0000] {taskinstance.py:2191} INFO - Executing <Task(BranchPythonOperator): choose_best_model> on 2024-03-21 03:03:56.204458+00:00
[2024-03-21T03:04:00.627+0000] {standard_task_runner.py:60} INFO - Started process 100 to run task
[2024-03-21T03:04:00.641+0000] {standard_task_runner.py:87} INFO - Running: ['***', 'tasks', 'run', 'my_dag', 'choose_best_model', 'manual__2024-03-21T03:03:56.204458+00:00', '--job-id', '6', '--raw', '--subdir', 'DAGS_FOLDER/my_dag.py', '--cfg-path', '/tmp/tmpkcrsly3x']
[2024-03-21T03:04:00.653+0000] {standard_task_runner.py:88} INFO - Job 6: Subtask choose_best_model
[2024-03-21T03:04:00.831+0000] {task_command.py:423} INFO - Running <TaskInstance: my_dag.choose_best_model manual__2024-03-21T03:03:56.204458+00:00 [running]> on host 0bc8edee533b
[2024-03-21T03:04:01.028+0000] {taskinstance.py:2480} INFO - Exporting env vars: AIRFLOW_CTX_DAG_OWNER='***' AIRFLOW_CTX_DAG_ID='my_dag' AIRFLOW_CTX_TASK_ID='choose_best_model' AIRFLOW_CTX_EXECUTION_DATE='2024-03-21T03:03:56.204458+00:00' AIRFLOW_CTX_TRY_NUMBER='1' AIRFLOW_CTX_DAG_RUN_ID='manual__2024-03-21T03:03:56.204458+00:00'
[2024-03-21T03:04:01.053+0000] {taskinstance.py:2698} ERROR - Task failed with exception
Traceback (most recent call last):
  File "/home/airflow/.local/lib/python3.8/site-packages/airflow/models/taskinstance.py", line 433, in _execute_task
    result = execute_callable(context=context, **execute_callable_kwargs)
  File "/home/airflow/.local/lib/python3.8/site-packages/airflow/operators/python.py", line 233, in execute
    return self.do_branch(context, super().execute(context))
  File "/home/airflow/.local/lib/python3.8/site-packages/airflow/operators/python.py", line 199, in execute
    return_value = self.execute_callable()
  File "/home/airflow/.local/lib/python3.8/site-packages/airflow/operators/python.py", line 216, in execute_callable
    return self.python_callable(*self.op_args, **self.op_kwargs)
  File "/opt/airflow/dags/my_dag.py", line 14, in _choose_best_model
    best_accuracy = max(accuracies)
ValueError: max() arg is an empty sequence
[2024-03-21T03:04:01.069+0000] {taskinstance.py:1138} INFO - Marking task as FAILED. dag_id=my_dag, task_id=choose_best_model, execution_date=20240321T030356, start_date=20240321T030400, end_date=20240321T030401
[2024-03-21T03:04:01.095+0000] {standard_task_runner.py:107} ERROR - Failed to execute job 6 for task choose_best_model (max() arg is an empty sequence; 100)
[2024-03-21T03:04:01.144+0000] {local_task_job_runner.py:234} INFO - Task exited with return code 1
[2024-03-21T03:04:01.190+0000] {taskinstance.py:3280} INFO - 0 downstream tasks scheduled from follow-on schedule check
