[2024-03-22T01:00:27.350+0000] {taskinstance.py:1956} INFO - Dependencies all met for dep_context=non-requeueable deps ti=<TaskInstance: api_dag.is_api_active manual__2024-03-22T01:00:25.913971+00:00 [queued]>
[2024-03-22T01:00:27.359+0000] {taskinstance.py:1956} INFO - Dependencies all met for dep_context=requeueable deps ti=<TaskInstance: api_dag.is_api_active manual__2024-03-22T01:00:25.913971+00:00 [queued]>
[2024-03-22T01:00:27.360+0000] {taskinstance.py:2170} INFO - Starting attempt 1 of 1
[2024-03-22T01:00:27.371+0000] {taskinstance.py:2191} INFO - Executing <Task(HttpSensor): is_api_active> on 2024-03-22 01:00:25.913971+00:00
[2024-03-22T01:00:27.376+0000] {standard_task_runner.py:60} INFO - Started process 69 to run task
[2024-03-22T01:00:27.379+0000] {standard_task_runner.py:87} INFO - Running: ['***', 'tasks', 'run', 'api_dag', 'is_api_active', 'manual__2024-03-22T01:00:25.913971+00:00', '--job-id', '115', '--raw', '--subdir', 'DAGS_FOLDER/test_calendarific.py', '--cfg-path', '/tmp/tmpoe931qr6']
[2024-03-22T01:00:27.381+0000] {standard_task_runner.py:88} INFO - Job 115: Subtask is_api_active
[2024-03-22T01:00:27.417+0000] {task_command.py:423} INFO - Running <TaskInstance: api_dag.is_api_active manual__2024-03-22T01:00:25.913971+00:00 [running]> on host 4b8b907c2725
[2024-03-22T01:00:27.470+0000] {taskinstance.py:2480} INFO - Exporting env vars: AIRFLOW_CTX_DAG_OWNER='***' AIRFLOW_CTX_DAG_ID='api_dag' AIRFLOW_CTX_TASK_ID='is_api_active' AIRFLOW_CTX_EXECUTION_DATE='2024-03-22T01:00:25.913971+00:00' AIRFLOW_CTX_TRY_NUMBER='1' AIRFLOW_CTX_DAG_RUN_ID='manual__2024-03-22T01:00:25.913971+00:00'
[2024-03-22T01:00:27.472+0000] {http.py:130} INFO - Poking: holidays/
[2024-03-22T01:00:27.480+0000] {base.py:83} INFO - Using connection ID 'calendar_api' for task execution.
[2024-03-22T01:00:28.970+0000] {http.py:178} ERROR - HTTP error: Unauthorized
[2024-03-22T01:00:28.970+0000] {http.py:179} ERROR - {"meta":{"code":401,"error_type":"auth failed","error_detail":"Missing or invalid api credentials. See https:\/\/calendarific.com\/api-documentation for details."},"response":[]}
[2024-03-22T01:00:28.978+0000] {taskinstance.py:2698} ERROR - Task failed with exception
Traceback (most recent call last):
  File "/home/airflow/.local/lib/python3.8/site-packages/airflow/providers/http/hooks/http.py", line 176, in check_response
    response.raise_for_status()
  File "/home/airflow/.local/lib/python3.8/site-packages/requests/models.py", line 1021, in raise_for_status
    raise HTTPError(http_error_msg, response=self)
requests.exceptions.HTTPError: 401 Client Error: Unauthorized for url: https://calendarific.com/api/v2/holidays

During handling of the above exception, another exception occurred:

Traceback (most recent call last):
  File "/home/airflow/.local/lib/python3.8/site-packages/airflow/models/taskinstance.py", line 433, in _execute_task
    result = execute_callable(context=context, **execute_callable_kwargs)
  File "/home/airflow/.local/lib/python3.8/site-packages/airflow/sensors/base.py", line 265, in execute
    raise e
  File "/home/airflow/.local/lib/python3.8/site-packages/airflow/sensors/base.py", line 247, in execute
    poke_return = self.poke(context)
  File "/home/airflow/.local/lib/python3.8/site-packages/airflow/providers/http/sensors/http.py", line 148, in poke
    raise exc
  File "/home/airflow/.local/lib/python3.8/site-packages/airflow/providers/http/sensors/http.py", line 132, in poke
    response = hook.run(
  File "/home/airflow/.local/lib/python3.8/site-packages/airflow/providers/http/hooks/http.py", line 166, in run
    return self.run_and_check(session, prepped_request, extra_options)
  File "/home/airflow/.local/lib/python3.8/site-packages/airflow/providers/http/hooks/http.py", line 217, in run_and_check
    self.check_response(response)
  File "/home/airflow/.local/lib/python3.8/site-packages/airflow/providers/http/hooks/http.py", line 180, in check_response
    raise AirflowException(str(response.status_code) + ":" + response.reason)
airflow.exceptions.AirflowException: 401:Unauthorized
[2024-03-22T01:00:28.980+0000] {taskinstance.py:1138} INFO - Marking task as FAILED. dag_id=api_dag, task_id=is_api_active, execution_date=20240322T010025, start_date=20240322T010027, end_date=20240322T010028
[2024-03-22T01:00:28.994+0000] {standard_task_runner.py:107} ERROR - Failed to execute job 115 for task is_api_active (401:Unauthorized; 69)
[2024-03-22T01:00:29.039+0000] {local_task_job_runner.py:234} INFO - Task exited with return code 1
[2024-03-22T01:00:29.052+0000] {taskinstance.py:3280} INFO - 0 downstream tasks scheduled from follow-on schedule check
